
 make.py started: 2016-08-01 11:38:46 /Users/Frank/Desktop/gslab_python/ebt_records 


Path: gslab_make
URL: https://econ-gentzkow-svn.stanford.edu/repos/main/trunk/lib/python/gslab_make
Repository Root: https://econ-gentzkow-svn.stanford.edu/repos/main
Repository UUID: 89b4331b-4301-411a-8e06-9c78d9cdb83d
Revision: 34785
Node Kind: directory
Last Changed Author: jwchoi2
Last Changed Rev: 33502
Last Changed Date: 2016-02-07 17:40:17 -0800 (Sun, 07 Feb 2016)


 get_externals.py started: 2016-08-01 11:38:46 /Users/Frank/Desktop/gslab_python/ebt_records

 Input was: "25834	%svn%/lib/stata/gslab_misc	*	./lib/stata/gslab_misc	""""	".
SVN command passed: https://econ-gentzkow-svn.stanford.edu/repos/main/trunk/lib/stata/gslab_misc/ @25834 exported to ./external./lib/stata/gslab_misc/.

 Input was: "27080	%svn%/lib/third_party/stata_tools	*	./lib/third_party/stata_tools	""""".
SVN command passed: https://econ-gentzkow-svn.stanford.edu/repos/main/trunk/lib/third_party/stata_tools/ @27080 exported to ./external./lib/third_party/stata_tools/.

 Input was: "185	%svn_retail2%/raw/EBT Records/links	links.txt	./	ebt_records_links.txt	""""".


Traceback (most recent call last):
  File "/Library/Python/2.7/site-packages/gslab_make/py/get_externals.py", line 31, in get_externals
    directive.issue_sys_command(quiet)
  File "/Library/Python/2.7/site-packages/gslab_make/py/private/getexternalsdirectives.py", line 129, in issue_sys_command
    self.command(quiet)
  File "/Library/Python/2.7/site-packages/gslab_make/py/private/getexternalsdirectives.py", line 275, in command
    self.rev, self.outdir, self.outfile), shell=True)
  File "/System/Library/Frameworks/Python.framework/Versions/2.7/lib/python2.7/subprocess.py", line 540, in check_call
    raise CalledProcessError(retcode, cmd)
CalledProcessError: Command 'svn export --force -r185 "file:///data/svn/repository/retailer2/trunk/raw/EBT Records/links/links.txt@185" "./externalebt_records_links.txt"' returned non-zero exit status 1

 get_externals.py ended: 2016-08-01 11:38:48
